Workbook
Name Slicer_NAMA_KABUPATEN: #REF!
Name Slicer_NAMA_KECAMATAN: #REF!
Name Slicer_ISP2: #REF!

Sheet Data Master
A2: NO | B2: NAMA KABUPATEN | C2: NAMA KECAMATAN | D2: NAMA DESA | E2: TITIK PEMASANGAN | F2: KOORDINAT LINTANG | G2: KOORDINAT BUJUR | H2: ISP | I2: PRODUK | J2: Bandwitdh / Kuota | K2: STATUS | L2: JANUARI | M2: FEBRUARI | N2: MARET | O2: APRIL | P2: MEI | Q2: JUNI | R2: JULI | S2: AGUSTUS | T2: SEPTEMBER | U2: HASIL EVALUASI | V2: LISTRIK | W2: JUMLAH PENDUDUK (JIWA) | X2: SMA/SMK | Y2: BIAYA BULANAN | Z2: LINK
A3: 1 | B3: BERAU | C3: BATU PUTIH | D3: TEMBUDAN | E3: KANTOR DESA | F3: 1.4114940697991807 | G3: 118.35868228189355 | H3: TELKOM | I3: WMS | J3: Bandwidth 50Mbps | K3: TERPASANG | U3: =IFERROR(__xludf.DUMMYFUNCTION("LET( angka_murni, ARRAYFORMULA(IFERROR(VALUE(REGEXREPLACE(L3:T3, ""[^0-9]"", """")), 0)), rata, IFERROR(AVERAGEIF(angka_murni, "">0""), 0), IF(rata > 0, IF(rata > 500, ""SANGAT OPTIMAL"", IF(rata > 200, ""OPTIMAL"", IF(rata > 100, ""K"&"URANG OPTIMAL"", ""TIDAK OPTIMAL""))), IF(COUNTIF(L3:T3, ""*TIDAK TERDETEKSI*"") > 0, ""TIDAK TERDETEKSI"", IF(COUNTIF(L3:T3, ""*TIDAK AKTIF*"") > 0, ""TIDAK AKTIF"", IF(COUNTIF(L3:T3, ""*BELUM TERPASANG*"") > 0, ""BELUM TERPASANG"", ""TI"&"DAK AKTIF""))) ) )"),"TIDAK AKTIF") -> TIDAK AKTIF | V3: PLN | W3: 2277 | X3: SMAN 10 BERAU | Y3: 638250 | Z3: https://tembudan.digitaldesa.id/
A4: =A3+1 -> 2 | B4: BERAU | C4: BATU PUTIH | D4: KAYU INDAH | E4: KANTOR DESA | F4: 1.4322942440867155 | G4: 118.31393952860488 | H4: TELKOMSEL | I4: ORBIT | J4: Kuota 400Gb | K4: TERPASANG | N4: <= 150GB | O4: <= 150GB | P4: <= 150GB | Q4: 0GB | R4: 0GB | U4: =IFERROR(__xludf.DUMMYFUNCTION("LET( angka_murni, ARRAYFORMULA(IFERROR(VALUE(REGEXREPLACE(L4:T4, ""[^0-9]"", """")), 0)), rata, IFERROR(AVERAGEIF(angka_murni, "">0""), 0), IF(rata > 0, IF(rata > 500, ""SANGAT OPTIMAL"", IF(rata > 200, ""OPTIMAL"", IF(rata > 100, ""K"&"URANG OPTIMAL"", ""TIDAK OPTIMAL""))), IF(COUNTIF(L4:T4, ""*TIDAK TERDETEKSI*"") > 0, ""TIDAK TERDETEKSI"", IF(COUNTIF(L4:T4, ""*TIDAK AKTIF*"") > 0, ""TIDAK AKTIF"", IF(COUNTIF(L4:T4, ""*BELUM TERPASANG*"") > 0, ""BELUM TERPASANG"", ""TI"&"DAK AKTIF""))) ) )"),"KURANG OPTIMAL") -> KURANG OPTIMAL | V4: PLN | W4: 921 | X4: SMAN 10 BERAU | Y4: 768950 | Z4: https://kayuindah.id/
A5: =A4+1 -> 3 | B5: BERAU | C5: BATU PUTIH | D5: BATU PUTIH | E5: KANTOR DESA | F5: 1.3724255224541961 | G5: 118.43450953203936 | H5: TELKOM | I5: WMS | J5: Bandwidth 50Mbps | K5: TERPASANG | U5: =IFERROR(__xludf.DUMMYFUNCTION("LET( angka_murni, ARRAYFORMULA(IFERROR(VALUE(REGEXREPLACE(L5:T5, ""[^0-9]"", """")), 0)), rata, IFERROR(AVERAGEIF(angka_murni, "">0""), 0), IF(rata > 0, IF(rata > 500, ""SANGAT OPTIMAL"", IF(rata > 200, ""OPTIMAL"", IF(rata > 100, ""K"&"URANG OPTIMAL"", ""TIDAK OPTIMAL""))), IF(COUNTIF(L5:T5, ""*TIDAK TERDETEKSI*"") > 0, ""TIDAK TERDETEKSI"", IF(COUNTIF(L5:T5, ""*TIDAK AKTIF*"") > 0, ""TIDAK AKTIF"", IF(COUNTIF(L5:T5, ""*BELUM TERPASANG*"") > 0, ""BELUM TERPASANG"", ""TI"&"DAK AKTIF""))) ) )"),"TIDAK AKTIF") -> TIDAK AKTIF | V5: PLN | W5: 3555 | X5: SMAN 10 BERAU | Y5: 638250 | Z5: https://kampungbatuputih.com/
A6: =A5+1 -> 4 | B6: BERAU | C6: BATU PUTIH | D6: LOBANG KELATAK | E6: KANTOR DESA | F6: 1.3696535243221635 | G6: 118.43360512047137 | H6: TELKOMSAT | I6: STARLINK | J6: Kuota FUP 2000GB | K6: TERPASANG | N6: <= 150GB | O6: <= 150GB | P6: <= 100GB | U6: =IFERROR(__xludf.DUMMYFUNCTION("LET( angka_murni, ARRAYFORMULA(IFERROR(VALUE(REGEXREPLACE(L6:T6, ""[^0-9]"", """")), 0)), rata, IFERROR(AVERAGEIF(angka_murni, "">0""), 0), IF(rata > 0, IF(rata > 500, ""SANGAT OPTIMAL"", IF(rata > 200, ""OPTIMAL"", IF(rata > 100, ""K"&"URANG OPTIMAL"", ""TIDAK OPTIMAL""))), IF(COUNTIF(L6:T6, ""*TIDAK TERDETEKSI*"") > 0, ""TIDAK TERDETEKSI"", IF(COUNTIF(L6:T6, ""*TIDAK AKTIF*"") > 0, ""TIDAK AKTIF"", IF(COUNTIF(L6:T6, ""*BELUM TERPASANG*"") > 0, ""BELUM TERPASANG"", ""TI"&"DAK AKTIF""))) ) )"),"KURANG OPTIMAL") -> KURANG OPTIMAL | V6: PLN | W6: 505 | X6: SMAN 10 BERAU | Y6: 1665000 | Z6: https://kampungbatuputih.com/
A7: =A6+1 -> 5 | B7: BERAU | C7: BATU PUTIH | D7: AMPEN MEDANG | E7: KANTOR DESA | F7: 1.336828851288219 | G7: 118.47551684091498 | H7: TELKOMSEL | I7: ORBIT | J7: Kuota 400Gb | K7: TERPASANG | N7: <= 100GB | O7: <= 100GB | P7: <= 100GB | Q7: <= 50GB | R7: <= 100GB | U7: =IFERROR(__xludf.DUMMYFUNCTION("LET( angka_murni, ARRAYFORMULA(IFERROR(VALUE(REGEXREPLACE(L7:T7, ""[^0-9]"", """")), 0)), rata, IFERROR(AVERAGEIF(angka_murni, "">0""), 0), IF(rata > 0, IF(rata > 500, ""SANGAT OPTIMAL"", IF(rata > 200, ""OPTIMAL"", IF(rata > 100, ""K"&"URANG OPTIMAL"", ""TIDAK OPTIMAL""))), IF(COUNTIF(L7:T7, ""*TIDAK TERDETEKSI*"") > 0, ""TIDAK TERDETEKSI"", IF(COUNTIF(L7:T7, ""*TIDAK AKTIF*"") > 0, ""TIDAK AKTIF"", IF(COUNTIF(L7:T7, ""*BELUM TERPASANG*"") > 0, ""BELUM TERPASANG"", ""TI"&"DAK AKTIF""))) ) )"),"TIDAK OPTIMAL") -> TIDAK OPTIMAL | V7: PLN | W7: 941 | X7: SMAN 10 BERAU | Y7: 768950
A8: =A7+1 -> 6 | B8: BERAU | C8: BATU PUTIH | D8: BALIKUKUP | E8: KANTOR DESA | F8: 1.417831510111881 | G8: 118.48055756225688 | H8: COMTELINDO | I8: WMS | J8: Bandwidth 30Mbps | K8: TERPASANG | L8: >1000GB | M8: >1000GB | N8: >1000GB | O8: >1000GB | P8: <= 200GB | Q8: <=1000GB | R8: <=1000GB | U8: =IFERROR(__xludf.DUMMYFUNCTION("LET( angka_murni, ARRAYFORMULA(IFERROR(VALUE(REGEXREPLACE(L8:T8, ""[^0-9]"", """")), 0)), rata, IFERROR(AVERAGEIF(angka_murni, "">0""), 0), IF(rata > 0, IF(rata > 500, ""SANGAT OPTIMAL"", IF(rata > 200, ""OPTIMAL"", IF(rata > 100, ""K"&"URANG OPTIMAL"", ""TIDAK OPTIMAL""))), IF(COUNTIF(L8:T8, ""*TIDAK TERDETEKSI*"") > 0, ""TIDAK TERDETEKSI"", IF(COUNTIF(L8:T8, ""*TIDAK AKTIF*"") > 0, ""TIDAK AKTIF"", IF(COUNTIF(L8:T8, ""*BELUM TERPASANG*"") > 0, ""BELUM TERPASANG"", ""TI"&"DAK AKTIF""))) ) )"),"SANGAT OPTIMAL") -> SANGAT OPTIMAL | V8: Non PLN : PLTS TERPUSAT KESDM 2016/2017 | W8: 1282 | X8: SMAN 10 BERAU | Y8: 1665000
A9: =A8+1 -> 7 | B9: BERAU | C9: BATU PUTIH | D9: SUMBER AGUNG | E9: KANTOR DESA | F9: 1.4578195365757132 | G9: 118.31199995866533 | H9: TELKOMSEL | I9: ORBIT | J9: Kuota 400Gb | K9: TERPASANG | N9: 0GB | O9: 0GB | P9: 0GB | Q9: 0GB | R9: 0GB | U9: =IFERROR(__xludf.DUMMYFUNCTION("LET( angka_murni, ARRAYFORMULA(IFERROR(VALUE(REGEXREPLACE(L9:T9, ""[^0-9]"", """")), 0)), rata, IFERROR(AVERAGEIF(angka_murni, "">0""), 0), IF(rata > 0, IF(rata > 500, ""SANGAT OPTIMAL"", IF(rata > 200, ""OPTIMAL"", IF(rata > 100, ""K"&"URANG OPTIMAL"", ""TIDAK OPTIMAL""))), IF(COUNTIF(L9:T9, ""*TIDAK TERDETEKSI*"") > 0, ""TIDAK TERDETEKSI"", IF(COUNTIF(L9:T9, ""*TIDAK AKTIF*"") > 0, ""TIDAK AKTIF"", IF(COUNTIF(L9:T9, ""*BELUM TERPASANG*"") > 0, ""BELUM TERPASANG"", ""TI"&"DAK AKTIF""))) ) )"),"TIDAK AKTIF") -> TIDAK AKTIF | V9: PLN | W9: 829 | X9: SMAN 10 BERAU | Y9: 768950 | Z9: https://sumberagung.digitaldesa.id/
A10: =A9+1 -> 8 | B10: BERAU | C10: BIATAN | D10: BIATAN ULU | E10: KANTOR DESA | F10: 1.335551728209252 | G10: 117.91302325587445 | H10: COMTELINDO | I10: WMS | J10: Bandwidth 30Mbps | K10: TERPASANG | L10: >1000GB | M10: >1000GB | N10: >1000GB | O10: >1000GB | P10: >1000GB | Q10: >1000GB | R10: >1000GB | U10: =IFERROR(__xludf.DUMMYFUNCTION("LET( angka_murni, ARRAYFORMULA(IFERROR(VALUE(REGEXREPLACE(L10:T10, ""[^0-9]"", """")), 0)), rata, IFERROR(AVERAGEIF(angka_murni, "">0""), 0), IF(rata > 0, IF(rata > 500, ""SANGAT OPTIMAL"", IF(rata > 200, ""OPTIMAL"", IF(rata > 100, "&"""KURANG OPTIMAL"", ""TIDAK OPTIMAL""))), IF(COUNTIF(L10:T10, ""*TIDAK TERDETEKSI*"") > 0, ""TIDAK TERDETEKSI"", IF(COUNTIF(L10:T10, ""*TIDAK AKTIF*"") > 0, ""TIDAK AKTIF"", IF(COUNTIF(L10:T10, ""*BELUM TERPASANG*"") > 0, ""BELUM TERPASAN"&"G"", ""TIDAK AKTIF""))) ) )"),"SANGAT OPTIMAL") -> SANGAT OPTIMAL | V10: PLN | W10: 921 | X10: SMAN 14 BERAU | Y10: 1665000
A11: =A10+1 -> 9 | B11: BERAU | C11: BIATAN | D11: BIATAN ILIR | E11: KANTOR DESA | F11: 1.6642044191360845 | G11: 118.05895755623887 | H11: COMTELINDO | I11: WMS | J11: Bandwidth 30Mbps | K11: TERPASANG | L11: BELUM TERPASANG | M11: BELUM TERPASANG | N11: BELUM TERPASANG | O11: TIDAK TERDETEKSI | P11: <= 50GB | Q11: <= 150GB | R11: <= 500GB | U11: =IFERROR(__xludf.DUMMYFUNCTION("LET( angka_murni, ARRAYFORMULA(IFERROR(VALUE(REGEXREPLACE(L11:T11, ""[^0-9]"", """")), 0)), rata, IFERROR(AVERAGEIF(angka_murni, "">0""), 0), IF(rata > 0, IF(rata > 500, ""SANGAT OPTIMAL"", IF(rata > 200, ""OPTIMAL"", IF(rata > 100, "&"""KURANG OPTIMAL"", ""TIDAK OPTIMAL""))), IF(COUNTIF(L11:T11, ""*TIDAK TERDETEKSI*"") > 0, ""TIDAK TERDETEKSI"", IF(COUNTIF(L11:T11, ""*TIDAK AKTIF*"") > 0, ""TIDAK AKTIF"", IF(COUNTIF(L11:T11, ""*BELUM TERPASANG*"") > 0, ""BELUM TERPASAN"&"G"", ""TIDAK AKTIF""))) ) )"),"OPTIMAL") -> OPTIMAL | V11: PLN | W11: 1400 | X11: SMAN 14 BERAU | Y11: 1665000 | Z11: https://biatanilir.berdesa.id/
A12: =A11+1 -> 10 | B12: BERAU | C12: BIATAN | D12: KARANGAN | E12: KANTOR DESA | F12: 1.664768 | G12: 118.055052 | H12: BESTCAMP | I12: STARLINK | J12: Kuota FUP 100GB | K12: TERPASANG | L12: <= 500GB | M12: <= 500GB | N12: <= 150GB | O12: <= 150GB | P12: <= 150GB | Q12: <= 200GB | U12: =IFERROR(__xludf.DUMMYFUNCTION("LET( angka_murni, ARRAYFORMULA(IFERROR(VALUE(REGEXREPLACE(L12:T12, ""[^0-9]"", """")), 0)), rata, IFERROR(AVERAGEIF(angka_murni, "">0""), 0), IF(rata > 0, IF(rata > 500, ""SANGAT OPTIMAL"", IF(rata > 200, ""OPTIMAL"", IF(rata > 100, "&"""KURANG OPTIMAL"", ""TIDAK OPTIMAL""))), IF(COUNTIF(L12:T12, ""*TIDAK TERDETEKSI*"") > 0, ""TIDAK TERDETEKSI"", IF(COUNTIF(L12:T12, ""*TIDAK AKTIF*"") > 0, ""TIDAK AKTIF"", IF(COUNTIF(L12:T12, ""*BELUM TERPASANG*"") > 0, ""BELUM TERPASAN"&"G"", ""TIDAK AKTIF""))) ) )"),"OPTIMAL") -> OPTIMAL | V12: PLN | W12: 667 | X12: SMAN 14 BERAU | Y12: 2553000 | Z12: https://desakarangan.id/
A13: =A12+1 -> 11 | B13: BERAU | C13: BIATAN | D13: BIATAN LEMPAKE | E13: KANTOR DESA | F13: 1.6636596092541116 | G13: 118.02909364298678 | H13: TELKOM | I13: WMS | J13: Bandwidth 50Mbps | K13: TERPASANG | U13: =IFERROR(__xludf.DUMMYFUNCTION("LET( angka_murni, ARRAYFORMULA(IFERROR(VALUE(REGEXREPLACE(L13:T13, ""[^0-9]"", """")), 0)), rata, IFERROR(AVERAGEIF(angka_murni, "">0""), 0), IF(rata > 0, IF(rata > 500, ""SANGAT OPTIMAL"", IF(rata > 200, ""OPTIMAL"", IF(rata > 100, "&"""KURANG OPTIMAL"", ""TIDAK OPTIMAL""))), IF(COUNTIF(L13:T13, ""*TIDAK TERDETEKSI*"") > 0, ""TIDAK TERDETEKSI"", IF(COUNTIF(L13:T13, ""*TIDAK AKTIF*"") > 0, ""TIDAK AKTIF"", IF(COUNTIF(L13:T13, ""*BELUM TERPASANG*"") > 0, ""BELUM TERPASAN"&"G"", ""TIDAK AKTIF""))) ) )"),"TIDAK AKTIF") -> TIDAK AKTIF | V13: PLN | W13: 3112 | X13: SMAN 14 BERAU | Y13: 638250 | Z13: https://biatan-lempake.geodesa.id/
A14: =A13+1 -> 12 | B14: BERAU | C14: BIATAN | D14: MANUNGGAL JAYA | E14: KANTOR DESA | F14: 1.68341854814553 | G14: 118.0118597 | H14: TELKOM | I14: WMS | J14: Bandwidth 50Mbps | K14: TERPASANG | U14: =IFERROR(__xludf.DUMMYFUNCTION("LET( angka_murni, ARRAYFORMULA(IFERROR(VALUE(REGEXREPLACE(L14:T14, ""[^0-9]"", """")), 0)), rata, IFERROR(AVERAGEIF(angka_murni, "">0""), 0), IF(rata > 0, IF(rata > 500, ""SANGAT OPTIMAL"", IF(rata > 200, ""OPTIMAL"", IF(rata > 100, "&"""KURANG OPTIMAL"", ""TIDAK OPTIMAL""))), IF(COUNTIF(L14:T14, ""*TIDAK TERDETEKSI*"") > 0, ""TIDAK TERDETEKSI"", IF(COUNTIF(L14:T14, ""*TIDAK AKTIF*"") > 0, ""TIDAK AKTIF"", IF(COUNTIF(L14:T14, ""*BELUM TERPASANG*"") > 0, ""BELUM TERPASAN"&"G"", ""TIDAK AKTIF""))) ) )"),"TIDAK AKTIF") -> TIDAK AKTIF | V14: PLN | W14: 1372 | X14: SMAN 14 BERAU | Y14: 638250
A15: =A14+1 -> 13 | B15: BERAU | C15: BIATAN | D15: BIATAN BAPINANG | E15: KANTOR DESA | F15: 1.714376961620032 | G15: 117.98620198580738 | H15: TELKOMSEL | I15: ORBIT | J15: Kuota 400Gb | K15: TERPASANG | N15: <= 200GB | O15: <= 200GB | P15: <= 200GB | Q15: <= 200GB | R15: <= 150GB | U15: =IFERROR(__xludf.DUMMYFUNCTION("LET( angka_murni, ARRAYFORMULA(IFERROR(VALUE(REGEXREPLACE(L15:T15, ""[^0-9]"", """")), 0)), rata, IFERROR(AVERAGEIF(angka_murni, "">0""), 0), IF(rata > 0, IF(rata > 500, ""SANGAT OPTIMAL"", IF(rata > 200, ""OPTIMAL"", IF(rata > 100, "&"""KURANG OPTIMAL"", ""TIDAK OPTIMAL""))), IF(COUNTIF(L15:T15, ""*TIDAK TERDETEKSI*"") > 0, ""TIDAK TERDETEKSI"", IF(COUNTIF(L15:T15, ""*TIDAK AKTIF*"") > 0, ""TIDAK AKTIF"", IF(COUNTIF(L15:T15, ""*BELUM TERPASANG*"") > 0, ""BELUM TERPASAN"&"G"", ""TIDAK AKTIF""))) ) )"),"KURANG OPTIMAL") -> KURANG OPTIMAL | V15: PLN | W15: 1003 | X15: SMAN 14 BERAU | Y15: 768950
A16: =A15+1 -> 14 | B16: BERAU | C16: BIATAN | D16: BIATAN BARU | E16: KANTOR DESA | F16: 1.5776146865362355 | G16: 117.98254060131111 | H16: COMTELINDO | I16: WMS | J16: Bandwidth 30Mbps | K16: TERPASANG | L16: <= 500GB | M16: <=1000GB | N16: <=1000GB | O16: <=1000GB | P16: >1000GB | Q16: <= 500GB | R16: <=1000GB | U16: =IFERROR(__xludf.DUMMYFUNCTION("LET( angka_murni, ARRAYFORMULA(IFERROR(VALUE(REGEXREPLACE(L16:T16, ""[^0-9]"", """")), 0)), rata, IFERROR(AVERAGEIF(angka_murni, "">0""), 0), IF(rata > 0, IF(rata > 500, ""SANGAT OPTIMAL"", IF(rata > 200, ""OPTIMAL"", IF(rata > 100, "&"""KURANG OPTIMAL"", ""TIDAK OPTIMAL""))), IF(COUNTIF(L16:T16, ""*TIDAK TERDETEKSI*"") > 0, ""TIDAK TERDETEKSI"", IF(COUNTIF(L16:T16, ""*TIDAK AKTIF*"") > 0, ""TIDAK AKTIF"", IF(COUNTIF(L16:T16, ""*BELUM TERPASANG*"") > 0, ""BELUM TERPASAN"&"G"", ""TIDAK AKTIF""))) ) )"),"SANGAT OPTIMAL") -> SANGAT OPTIMAL | V16: PLN | W16: 800 | X16: SMAN 14 BERAU | Y16: 1665000
A17: =A16+1 -> 15 | B17: BERAU | C17: BIATAN | D17: BUKIT MAKMUR JAYA | E17: PUSTU | F17: 1.6436982211065871 | G17: 117.9270624998015 | H17: COMTELINDO | I17: WMS | J17: Bandwidth 30Mbps | K17: TERPASANG | L17: TIDAK TERDETEKSI | M17: <= 100GB | N17: <= 100GB | O17: 0GB | P17: <= 50GB | Q17: <= 200GB | R17: <= 200GB | U17: =IFERROR(__xludf.DUMMYFUNCTION("LET( angka_murni, ARRAYFORMULA(IFERROR(VALUE(REGEXREPLACE(L17:T17, ""[^0-9]"", """")), 0)), rata, IFERROR(AVERAGEIF(angka_murni, "">0""), 0), IF(rata > 0, IF(rata > 500, ""SANGAT OPTIMAL"", IF(rata > 200, ""OPTIMAL"", IF(rata > 100, "&"""KURANG OPTIMAL"", ""TIDAK OPTIMAL""))), IF(COUNTIF(L17:T17, ""*TIDAK TERDETEKSI*"") > 0, ""TIDAK TERDETEKSI"", IF(COUNTIF(L17:T17, ""*TIDAK AKTIF*"") > 0, ""TIDAK AKTIF"", IF(COUNTIF(L17:T17, ""*BELUM TERPASANG*"") > 0, ""BELUM TERPASAN"&"G"", ""TIDAK AKTIF""))) ) )"),"KURANG OPTIMAL") -> KURANG OPTIMAL | V17: PLN | W17: 827 | X17: SMAN 14 BERAU | Y17: 1665000
A18: =A17+1 -> 16 | B18: BERAU | C18: BIDUK-BIDUK | D18: BIDUK-BIDUK | E18: KANTOR DESA | F18: 1.3102393782348722 | G18: 118.62564678631931 | H18: TELKOMSEL | I18: ORBIT | J18: Kuota 400Gb | K18: TERPASANG | N18: <= 100GB | O18: <= 100GB | P18: <= 100GB | Q18: <= 150GB | R18: <= 150GB | U18: =IFERROR(__xludf.DUMMYFUNCTION("LET( angka_murni, ARRAYFORMULA(IFERROR(VALUE(REGEXREPLACE(L18:T18, ""[^0-9]"", """")), 0)), rata, IFERROR(AVERAGEIF(angka_murni, "">0""), 0), IF(rata > 0, IF(rata > 500, ""SANGAT OPTIMAL"", IF(rata > 200, ""OPTIMAL"", IF(rata > 100, "&"""KURANG OPTIMAL"", ""TIDAK OPTIMAL""))), IF(COUNTIF(L18:T18, ""*TIDAK TERDETEKSI*"") > 0, ""TIDAK TERDETEKSI"", IF(COUNTIF(L18:T18, ""*TIDAK AKTIF*"") > 0, ""TIDAK AKTIF"", IF(COUNTIF(L18:T18, ""*BELUM TERPASANG*"") > 0, ""BELUM TERPASAN"&"G"", ""TIDAK AKTIF""))) ) )"),"KURANG OPTIMAL") -> KURANG OPTIMAL | V18: PLN | W18: 2260 | X18: SMAN 8 BERAU | Y18: 768950 | Z18: https://kampungbiduk.id/
A19: =A18+1 -> 17 | B19: BERAU | C19: BIDUK-BIDUK | D19: PANTAI HARAPAN | E19: KANTOR DESA | F19: 1.2859061874501128 | G19: 118.65429730385846 | H19: TELKOM | I19: WMS | J19: Bandwidth 50Mbps | K19: TERPASANG | U19: =IFERROR(__xludf.DUMMYFUNCTION("LET( angka_murni, ARRAYFORMULA(IFERROR(VALUE(REGEXREPLACE(L19:T19, ""[^0-9]"", """")), 0)), rata, IFERROR(AVERAGEIF(angka_murni, "">0""), 0), IF(rata > 0, IF(rata > 500, ""SANGAT OPTIMAL"", IF(rata > 200, ""OPTIMAL"", IF(rata > 100, "&"""KURANG OPTIMAL"", ""TIDAK OPTIMAL""))), IF(COUNTIF(L19:T19, ""*TIDAK TERDETEKSI*"") > 0, ""TIDAK TERDETEKSI"", IF(COUNTIF(L19:T19, ""*TIDAK AKTIF*"") > 0, ""TIDAK AKTIF"", IF(COUNTIF(L19:T19, ""*BELUM TERPASANG*"") > 0, ""BELUM TERPASAN"&"G"", ""TIDAK AKTIF""))) ) )"),"TIDAK AKTIF") -> TIDAK AKTIF | V19: PLN | W19: 863 | X19: SMAN 8 BERAU | Y19: 638250 | Z19: https://majupantaiharapan.com/
A20: =A19+1 -> 18 | B20: BERAU | C20: BIDUK-BIDUK | D20: TANJUNG PREPAT | E20: KANTOR DESA | F20: 1.3110253879927252 | G20: 118.62600528299706 | H20: TELKOM | I20: WMS | J20: Bandwidth 50Mbps | K20: TERPASANG | U20: =IFERROR(__xludf.DUMMYFUNCTION("LET( angka_murni, ARRAYFORMULA(IFERROR(VALUE(REGEXREPLACE(L20:T20, ""[^0-9]"", """")), 0)), rata, IFERROR(AVERAGEIF(angka_murni, "">0""), 0), IF(rata > 0, IF(rata > 500, ""SANGAT OPTIMAL"", IF(rata > 200, ""OPTIMAL"", IF(rata > 100, "&"""KURANG OPTIMAL"", ""TIDAK OPTIMAL""))), IF(COUNTIF(L20:T20, ""*TIDAK TERDETEKSI*"") > 0, ""TIDAK TERDETEKSI"", IF(COUNTIF(L20:T20, ""*TIDAK AKTIF*"") > 0, ""TIDAK AKTIF"", IF(COUNTIF(L20:T20, ""*BELUM TERPASANG*"") > 0, ""BELUM TERPASAN"&"G"", ""TIDAK AKTIF""))) ) )"),"TIDAK AKTIF") -> TIDAK AKTIF | V20: PLN | W20: 1129 | X20: SMAN 8 BERAU | Y20: 638250
A21: =A20+1 -> 19 | B21: BERAU | C21: BIDUK-BIDUK | D21: TELUK SUMBANG | E21: KANTOR DESA | F21: 1.047659997887953 | G21: 118.82834512867876 | H21: COMTELINDO | I21: WMS | J21: Bandwidth 30Mbps | K21: TERPASANG | L21: <=1000GB | M21: <= 500GB | N21: <=1000GB | O21: <= 500GB | P21: <= 500GB | Q21: <= 500GB | R21: <= 500GB | U21: =IFERROR(__xludf.DUMMYFUNCTION("LET( angka_murni, ARRAYFORMULA(IFERROR(VALUE(REGEXREPLACE(L21:T21, ""[^0-9]"", """")), 0)), rata, IFERROR(AVERAGEIF(angka_murni, "">0""), 0), IF(rata > 0, IF(rata > 500, ""SANGAT OPTIMAL"", IF(rata > 200, ""OPTIMAL"", IF(rata > 100, "&"""KURANG OPTIMAL"", ""TIDAK OPTIMAL""))), IF(COUNTIF(L21:T21, ""*TIDAK TERDETEKSI*"") > 0, ""TIDAK TERDETEKSI"", IF(COUNTIF(L21:T21, ""*TIDAK AKTIF*"") > 0, ""TIDAK AKTIF"", IF(COUNTIF(L21:T21, ""*BELUM TERPASANG*"") > 0, ""BELUM TERPASAN"&"G"", ""TIDAK AKTIF""))) ) )"),"SANGAT OPTIMAL") -> SANGAT OPTIMAL | V21: Non PLN : WILUS PLTS TERPUSAT | W21: 895 | X21: SMAN 8 BERAU | Y21: 1665000 | Z21: https://teluksumbang.digitaldesa.id/
A22: =A21+1 -> 20 | B22: BERAU | C22: BIDUK-BIDUK | D22: TELUK SULAIMAN | E22: KANTOR DESA | F22: 1.1749437584216023 | G22: 118.76764368946284 | H22: TELKOM | I22: WMS | J22: Bandwidth 50Mbps | K22: TERPASANG | U22: =IFERROR(__xludf.DUMMYFUNCTION("LET( angka_murni, ARRAYFORMULA(IFERROR(VALUE(REGEXREPLACE(L22:T22, ""[^0-9]"", """")), 0)), rata, IFERROR(AVERAGEIF(angka_murni, "">0""), 0), IF(rata > 0, IF(rata > 500, ""SANGAT OPTIMAL"", IF(rata > 200, ""OPTIMAL"", IF(rata > 100, "&"""KURANG OPTIMAL"", ""TIDAK OPTIMAL""))), IF(COUNTIF(L22:T22, ""*TIDAK TERDETEKSI*"") > 0, ""TIDAK TERDETEKSI"", IF(COUNTIF(L22:T22, ""*TIDAK AKTIF*"") > 0, ""TIDAK AKTIF"", IF(COUNTIF(L22:T22, ""*BELUM TERPASANG*"") > 0, ""BELUM TERPASAN"&"G"", ""TIDAK AKTIF""))) ) )"),"TIDAK AKTIF") -> TIDAK AKTIF | V22: PLN | W22: 1625 | X22: SMAN 8 BERAU | Y22: 638250
A23: =A22+1 -> 21 | B23: BERAU | C23: BIDUK-BIDUK | D23: GIRING-GIRING | E23: KANTOR DESA | F23: 1.2077694200696352 | G23: 118.7571945097419 | H23: TELKOM | I23: WMS | J23: Bandwidth 50Mbps | K23: TERPASANG | U23: =IFERROR(__xludf.DUMMYFUNCTION("LET( angka_murni, ARRAYFORMULA(IFERROR(VALUE(REGEXREPLACE(L23:T23, ""[^0-9]"", """")), 0)), rata, IFERROR(AVERAGEIF(angka_murni, "">0""), 0), IF(rata > 0, IF(rata > 500, ""SANGAT OPTIMAL"", IF(rata > 200, ""OPTIMAL"", IF(rata > 100, "&"""KURANG OPTIMAL"", ""TIDAK OPTIMAL""))), IF(COUNTIF(L23:T23, ""*TIDAK TERDETEKSI*"") > 0, ""TIDAK TERDETEKSI"", IF(COUNTIF(L23:T23, ""*TIDAK AKTIF*"") > 0, ""TIDAK AKTIF"", IF(COUNTIF(L23:T23, ""*BELUM TERPASANG*"") > 0, ""BELUM TERPASAN"&"G"", ""TIDAK AKTIF""))) ) )"),"TIDAK AKTIF") -> TIDAK AKTIF | V23: PLN | W23: 1368 | X23: SMAN 8 BERAU | Y23: 638250 | Z23: https://giring-giring.id/
A24: =A23+1 -> 22 | B24: BERAU | C24: GUNUNG TABUR | D24: TASUK | E24: PUSTU | F24: 2.1750066017231764 | G24: 117.4165095990138 | H24: COMTELINDO | I24: WMS | J24: Bandwidth 30Mbps | K24: TERPASANG | L24: <=1000GB | M24: <=1000GB | N24: >1000GB | O24: >1000GB | P24: >1000GB | Q24: <=1000GB | R24: <=1000GB | U24: =IFERROR(__xludf.DUMMYFUNCTION("LET( angka_murni, ARRAYFORMULA(IFERROR(VALUE(REGEXREPLACE(L24:T24, ""[^0-9]"", """")), 0)), rata, IFERROR(AVERAGEIF(angka_murni, "">0""), 0), IF(rata > 0, IF(rata > 500, ""SANGAT OPTIMAL"", IF(rata > 200, ""OPTIMAL"", IF(rata > 100, "&"""KURANG OPTIMAL"", ""TIDAK OPTIMAL""))), IF(COUNTIF(L24:T24, ""*TIDAK TERDETEKSI*"") > 0, ""TIDAK TERDETEKSI"", IF(COUNTIF(L24:T24, ""*TIDAK AKTIF*"") > 0, ""TIDAK AKTIF"", IF(COUNTIF(L24:T24, ""*BELUM TERPASANG*"") > 0, ""BELUM TERPASAN"&"G"", ""TIDAK AKTIF""))) ) )"),"SANGAT OPTIMAL") -> SANGAT OPTIMAL | V24: PLN | W24: 3242 | X24: SMKN 6 & SMAN 5 BERAU | Y24: 1665000
A25: =A24+1 -> 23 | B25: BERAU | C25: GUNUNG TABUR | D25: BIRANG | E25: KANTOR DESA | F25: 2.203806 | G25: 117.468896 | H25: BESTCAMP | I25: STARLINK | J25: Kuota FUP 100GB | K25: TERPASANG | L25: <= 100GB | M25: <= 100GB | N25: <= 100GB | O25: <= 100GB | P25: <= 150GB | Q25: <= 150GB | U25: =IFERROR(__xludf.DUMMYFUNCTION("LET( angka_murni, ARRAYFORMULA(IFERROR(VALUE(REGEXREPLACE(L25:T25, ""[^0-9]"", """")), 0)), rata, IFERROR(AVERAGEIF(angka_murni, "">0""), 0), IF(rata > 0, IF(rata > 500, ""SANGAT OPTIMAL"", IF(rata > 200, ""OPTIMAL"", IF(rata > 100, "&"""KURANG OPTIMAL"", ""TIDAK OPTIMAL""))), IF(COUNTIF(L25:T25, ""*TIDAK TERDETEKSI*"") > 0, ""TIDAK TERDETEKSI"", IF(COUNTIF(L25:T25, ""*TIDAK AKTIF*"") > 0, ""TIDAK AKTIF"", IF(COUNTIF(L25:T25, ""*BELUM TERPASANG*"") > 0, ""BELUM TERPASAN"&"G"", ""TIDAK AKTIF""))) ) )"),"KURANG OPTIMAL") -> KURANG OPTIMAL | V25: PLN | W25: 1211 | X25: SMKN 6 & SMAN 5 BERAU | Y25: 2553000
A26: =A25+1 -> 24 | B26: BERAU | C26: GUNUNG TABUR | D26: MALUANG | E26: KANTOR DESA | F26: 2.181368287478703 | G26: 117.51845002865578 | H26: TELKOM | I26: WMS | J26: Bandwidth 50Mbps | K26: TERPASANG | U26: =IFERROR(__xludf.DUMMYFUNCTION("LET( angka_murni, ARRAYFORMULA(IFERROR(VALUE(REGEXREPLACE(L26:T26, ""[^0-9]"", """")), 0)), rata, IFERROR(AVERAGEIF(angka_murni, "">0""), 0), IF(rata > 0, IF(rata > 500, ""SANGAT OPTIMAL"", IF(rata > 200, ""OPTIMAL"", IF(rata > 100, "&"""KURANG OPTIMAL"", ""TIDAK OPTIMAL""))), IF(COUNTIF(L26:T26, ""*TIDAK TERDETEKSI*"") > 0, ""TIDAK TERDETEKSI"", IF(COUNTIF(L26:T26, ""*TIDAK AKTIF*"") > 0, ""TIDAK AKTIF"", IF(COUNTIF(L26:T26, ""*BELUM TERPASANG*"") > 0, ""BELUM TERPASAN"&"G"", ""TIDAK AKTIF""))) ) )"),"TIDAK AKTIF") -> TIDAK AKTIF | V26: PLN | W26: 5400 | X26: SMKN 6 & SMAN 5 BERAU | Y26: 638250
A27: =A26+1 -> 25 | B27: BERAU | C27: GUNUNG TABUR | D27: SAMBURAKAT | E27: KANTOR DESA | F27: 2.1752313283484317 | G27: 117.54850596824551 | H27: TELKOM | I27: WMS | J27: Bandwidth 50Mbps | K27: TERPASANG | U27: =IFERROR(__xludf.DUMMYFUNCTION("LET( angka_murni, ARRAYFORMULA(IFERROR(VALUE(REGEXREPLACE(L27:T27, ""[^0-9]"", """")), 0)), rata, IFERROR(AVERAGEIF(angka_murni, "">0""), 0), IF(rata > 0, IF(rata > 500, ""SANGAT OPTIMAL"", IF(rata > 200, ""OPTIMAL"", IF(rata > 100, "&"""KURANG OPTIMAL"", ""TIDAK OPTIMAL""))), IF(COUNTIF(L27:T27, ""*TIDAK TERDETEKSI*"") > 0, ""TIDAK TERDETEKSI"", IF(COUNTIF(L27:T27, ""*TIDAK AKTIF*"") > 0, ""TIDAK AKTIF"", IF(COUNTIF(L27:T27, ""*BELUM TERPASANG*"") > 0, ""BELUM TERPASAN"&"G"", ""TIDAK AKTIF""))) ) )"),"TIDAK AKTIF") -> TIDAK AKTIF | V27: PLN | W27: 1832 | X27: SMKN 6 & SMAN 5 BERAU | Y27: 638250
A28: =A27+1 -> 26 | B28: BERAU | C28: GUNUNG TABUR | D28: SAMBAKUNGAN | E28: KANTOR DESA | F28: 2.21464690198614 | G28: 117.59864440813938 | H28: TELKOM | I28: WMS | J28: Bandwidth 50Mbps | K28: TERPASANG | U28: =IFERROR(__xludf.DUMMYFUNCTION("LET( angka_murni, ARRAYFORMULA(IFERROR(VALUE(REGEXREPLACE(L28:T28, ""[^0-9]"", """")), 0)), rata, IFERROR(AVERAGEIF(angka_murni, "">0""), 0), IF(rata > 0, IF(rata > 500, ""SANGAT OPTIMAL"", IF(rata > 200, ""OPTIMAL"", IF(rata > 100, "&"""KURANG OPTIMAL"", ""TIDAK OPTIMAL""))), IF(COUNTIF(L28:T28, ""*TIDAK TERDETEKSI*"") > 0, ""TIDAK TERDETEKSI"", IF(COUNTIF(L28:T28, ""*TIDAK AKTIF*"") > 0, ""TIDAK AKTIF"", IF(COUNTIF(L28:T28, ""*BELUM TERPASANG*"") > 0, ""BELUM TERPASAN"&"G"", ""TIDAK AKTIF""))) ) )"),"TIDAK AKTIF") -> TIDAK AKTIF | V28: PLN | W28: 2635 | X28: SMKN 6 & SMAN 5 BERAU | Y28: 638250
A29: =A28+1 -> 27 | B29: BERAU | C29: GUNUNG TABUR | D29: MERANCANG ULU | E29: KANTOR DESA | F29: 2.2055231147736314 | G29: 117.66521933715202 | H29: TELKOM | I29: WMS | J29: Bandwidth 50Mbps | K29: TERPASANG | U29: =IFERROR(__xludf.DUMMYFUNCTION("LET( angka_murni, ARRAYFORMULA(IFERROR(VALUE(REGEXREPLACE(L29:T29, ""[^0-9]"", """")), 0)), rata, IFERROR(AVERAGEIF(angka_murni, "">0""), 0), IF(rata > 0, IF(rata > 500, ""SANGAT OPTIMAL"", IF(rata > 200, ""OPTIMAL"", IF(rata > 100, "&"""KURANG OPTIMAL"", ""TIDAK OPTIMAL""))), IF(COUNTIF(L29:T29, ""*TIDAK TERDETEKSI*"") > 0, ""TIDAK TERDETEKSI"", IF(COUNTIF(L29:T29, ""*TIDAK AKTIF*"") > 0, ""TIDAK AKTIF"", IF(COUNTIF(L29:T29, ""*BELUM TERPASANG*"") > 0, ""BELUM TERPASAN"&"G"", ""TIDAK AKTIF""))) ) )"),"TIDAK AKTIF") -> TIDAK AKTIF | V29: PLN | W29: 2006 | X29: SMKN 6 & SMAN 5 BERAU | Y29: 638250
A30: =A29+1 -> 28 | B30: BERAU | C30: GUNUNG TABUR | D30: MERANCANG ILIR | E30: KANTOR DESA | F30: 2.2077451652035602 | G30: 117.67821572730058 | H30: COMTELINDO | I30: WMS | J30: Bandwidth 30Mbps | K30: TERPASANG | L30: TIDAK TERDETEKSI | M30: TIDAK TERDETEKSI | N30: <= 150GB | O30: <=1000GB | P30: <= 500GB | Q30: <= 50GB | R30: <= 1GB | U30: =IFERROR(__xludf.DUMMYFUNCTION("LET( angka_murni, ARRAYFORMULA(IFERROR(VALUE(REGEXREPLACE(L30:T30, ""[^0-9]"", """")), 0)), rata, IFERROR(AVERAGEIF(angka_murni, "">0""), 0), IF(rata > 0, IF(rata > 500, ""SANGAT OPTIMAL"", IF(rata > 200, ""OPTIMAL"", IF(rata > 100, "&"""KURANG OPTIMAL"", ""TIDAK OPTIMAL""))), IF(COUNTIF(L30:T30, ""*TIDAK TERDETEKSI*"") > 0, ""TIDAK TERDETEKSI"", IF(COUNTIF(L30:T30, ""*TIDAK AKTIF*"") > 0, ""TIDAK AKTIF"", IF(COUNTIF(L30:T30, ""*BELUM TERPASANG*"") > 0, ""BELUM TERPASAN"&"G"", ""TIDAK AKTIF""))) ) )"),"OPTIMAL") -> OPTIMAL | V30: PLN | W30: 1780 | X30: SMKN 6 & SMAN 5 BERAU | Y30: 1665000
A31: =A30+1 -> 29 | B31: BERAU | C31: GUNUNG TABUR | D31: PULAU BESING | E31: KANTOR DESA | F31: 2.196157985452608 | G31: 117.66001871418263 | H31: COMTELINDO | I31: WMS | J31: Bandwidth 30Mbps | K31: TERPASANG | L31: >1000GB | M31: >1000GB | N31: >1000GB | O31: <=1000GB | P31: >1000GB | Q31: >1000GB | R31: >1000GB | U31: =IFERROR(__xludf.DUMMYFUNCTION("LET( angka_murni, ARRAYFORMULA(IFERROR(VALUE(REGEXREPLACE(L31:T31, ""[^0-9]"", """")), 0)), rata, IFERROR(AVERAGEIF(angka_murni, "">0""), 0), IF(rata > 0, IF(rata > 500, ""SANGAT OPTIMAL"", IF(rata > 200, ""OPTIMAL"", IF(rata > 100, "&"""KURANG OPTIMAL"", ""TIDAK OPTIMAL""))), IF(COUNTIF(L31:T31, ""*TIDAK TERDETEKSI*"") > 0, ""TIDAK TERDETEKSI"", IF(COUNTIF(L31:T31, ""*TIDAK AKTIF*"") > 0, ""TIDAK AKTIF"", IF(COUNTIF(L31:T31, ""*BELUM TERPASANG*"") > 0, ""BELUM TERPASAN"&"G"", ""TIDAK AKTIF""))) ) )"),"SANGAT OPTIMAL") -> SANGAT OPTIMAL | V31: PLN | W31: 350 | X31: SMKN 6 & SMAN 5 BERAU | Y31: 1665000
A32: =A31+1 -> 30 | B32: BERAU | C32: GUNUNG TABUR | D32: MELATI JAYA | E32: KANTOR DESA | F32: 2.310769889243056 | G32: 117.67866987853196 | H32: TELKOMSEL | I32: ORBIT | J32: Kuota 400Gb | K32: TERPASANG | N32: <= 500GB | O32: <= 500GB | P32: <= 500GB | Q32: <= 500GB | R32: <= 500GB | U32: =IFERROR(__xludf.DUMMYFUNCTION("LET( angka_murni, ARRAYFORMULA(IFERROR(VALUE(REGEXREPLACE(L32:T32, ""[^0-9]"", """")), 0)), rata, IFERROR(AVERAGEIF(angka_murni, "">0""), 0), IF(rata > 0, IF(rata > 500, ""SANGAT OPTIMAL"", IF(rata > 200, ""OPTIMAL"", IF(rata > 100, "&"""KURANG OPTIMAL"", ""TIDAK OPTIMAL""))), IF(COUNTIF(L32:T32, ""*TIDAK TERDETEKSI*"") > 0, ""TIDAK TERDETEKSI"", IF(COUNTIF(L32:T32, ""*TIDAK AKTIF*"") > 0, ""TIDAK AKTIF"", IF(COUNTIF(L32:T32, ""*BELUM TERPASANG*"") > 0, ""BELUM TERPASAN"&"G"", ""TIDAK AKTIF""))) ) )"),"OPTIMAL") -> OPTIMAL | V32: PLN | W32: 1903 | X32: SMKN 6 & SMAN 5 BERAU | Y32: 768950
A33: =A32+1 -> 31 | B33: BERAU | C33: GUNUNG TABUR | D33: BATU-BATU | E33: TUGU KAMPUNG BATU-BATU | F33: 2.190497 | G33: 117.726881 | H33: BESTCAMP | I33: STARLINK | J33: Kuota FUP 100GB | K33: TERPASANG | L33: >1000GB | M33: >1000GB | N33: >1000GB | O33: <= 500GB | P33: <= 500GB | Q33: <= 500GB | U33: =IFERROR(__xludf.DUMMYFUNCTION("LET( angka_murni, ARRAYFORMULA(IFERROR(VALUE(REGEXREPLACE(L33:T33, ""[^0-9]"", """")), 0)), rata, IFERROR(AVERAGEIF(angka_murni, "">0""), 0), IF(rata > 0, IF(rata > 500, ""SANGAT OPTIMAL"", IF(rata > 200, ""OPTIMAL"", IF(rata > 100, "&"""KURANG OPTIMAL"", ""TIDAK OPTIMAL""))), IF(COUNTIF(L33:T33, ""*TIDAK TERDETEKSI*"") > 0, ""TIDAK TERDETEKSI"", IF(COUNTIF(L33:T33, ""*TIDAK AKTIF*"") > 0, ""TIDAK AKTIF"", IF(COUNTIF(L33:T33, ""*BELUM TERPASANG*"") > 0, ""BELUM TERPASAN"&"G"", ""TIDAK AKTIF""))) ) )"),"SANGAT OPTIMAL") -> SANGAT OPTIMAL | V33: PLN | W33: 755 | X33: SMKN 6 & SMAN 5 BERAU | Y33: 2553000
A34: =A33+1 -> 32 | B34: BERAU | C34: KELAY | D34: MERABU | E34: KANTOR DESA | F34: 1.5059370720888037 | G34: 117.27349770574065 | H34: COMTELINDO | I34: WMS | J34: Bandwidth 30Mbps | K34: TERPASANG | L34: <=1000GB | M34: <=1000GB | N34: <=1000GB | O34: >1000GB | P34: <=1000GB | Q34: >1000GB | R34: >1000GB | U34: =IFERROR(__xludf.DUMMYFUNCTION("LET( angka_murni, ARRAYFORMULA(IFERROR(VALUE(REGEXREPLACE(L34:T34, ""[^0-9]"", """")), 0)), rata, IFERROR(AVERAGEIF(angka_murni, "">0""), 0), IF(rata > 0, IF(rata > 500, ""SANGAT OPTIMAL"", IF(rata > 200, ""OPTIMAL"", IF(rata > 100, "&"""KURANG OPTIMAL"", ""TIDAK OPTIMAL""))), IF(COUNTIF(L34:T34, ""*TIDAK TERDETEKSI*"") > 0, ""TIDAK TERDETEKSI"", IF(COUNTIF(L34:T34, ""*TIDAK AKTIF*"") > 0, ""TIDAK AKTIF"", IF(COUNTIF(L34:T34, ""*BELUM TERPASANG*"") > 0, ""BELUM TERPASAN"&"G"", ""TIDAK AKTIF""))) ) )"),"SANGAT OPTIMAL") -> SANGAT OPTIMAL | V34: Non PLN : WILUS PLTS TERPUSAT | W34: 349 | X34: SMKN 4 BERAU | Y34: 1665000
A35: =A34+1 -> 33 | B35: BERAU | C35: KELAY | D35: PANAAN | E35: KANTOR DESA | F35: 1.5755555460826707 | G35: 117.30576330763839 | H35: COMTELINDO | I35: WMS | J35: Bandwidth 30Mbps | K35: TERPASANG | L35: TIDAK TERDETEKSI | M35: TIDAK TERDETEKSI | N35: <= 100GB | O35: <= 50GB | P35: <= 50GB | Q35: <= 1GB | R35: <= 10GB | U35: =IFERROR(__xludf.DUMMYFUNCTION("LET( angka_murni, ARRAYFORMULA(IFERROR(VALUE(REGEXREPLACE(L35:T35, ""[^0-9]"", """")), 0)), rata, IFERROR(AVERAGEIF(angka_murni, "">0""), 0), IF(rata > 0, IF(rata > 500, ""SANGAT OPTIMAL"", IF(rata > 200, ""OPTIMAL"", IF(rata > 100, "&"""KURANG OPTIMAL"", ""TIDAK OPTIMAL""))), IF(COUNTIF(L35:T35, ""*TIDAK TERDETEKSI*"") > 0, ""TIDAK TERDETEKSI"", IF(COUNTIF(L35:T35, ""*TIDAK AKTIF*"") > 0, ""TIDAK AKTIF"", IF(COUNTIF(L35:T35, ""*BELUM TERPASANG*"") > 0, ""BELUM TERPASAN"&"G"", ""TIDAK AKTIF""))) ) )"),"TIDAK OPTIMAL") -> TIDAK OPTIMAL | V35: Non PLN : Genset Desa/kampung,PLTS SHS | W35: 260 | X35: SMKN 4 BERAU | Y35: 1665000 | Z35: https://panaan-berau.desa.id/informasi_publik
A36: =A35+1 -> 34 | B36: BERAU | C36: KELAY | D36: MERAPUN | E36: KANTOR DESA | F36: 1.4572588294024136 | G36: 117.12644980952493 | H36: COMTELINDO | I36: WMS | J36: Bandwidth 30Mbps | K36: TERPASANG | L36: TIDAK TERDETEKSI | M36: <= 500GB | N36: >1000GB | O36: >1000GB | P36: >1000GB | Q36: >1000GB | R36: >1000GB | U36: =IFERROR(__xludf.DUMMYFUNCTION("LET( angka_murni, ARRAYFORMULA(IFERROR(VALUE(REGEXREPLACE(L36:T36, ""[^0-9]"", """")), 0)), rata, IFERROR(AVERAGEIF(angka_murni, "">0""), 0), IF(rata > 0, IF(rata > 500, ""SANGAT OPTIMAL"", IF(rata > 200, ""OPTIMAL"", IF(rata > 100, "&"""KURANG OPTIMAL"", ""TIDAK OPTIMAL""))), IF(COUNTIF(L36:T36, ""*TIDAK TERDETEKSI*"") > 0, ""TIDAK TERDETEKSI"", IF(COUNTIF(L36:T36, ""*TIDAK AKTIF*"") > 0, ""TIDAK AKTIF"", IF(COUNTIF(L36:T36, ""*BELUM TERPASANG*"") > 0, ""BELUM TERPASAN"&"G"", ""TIDAK AKTIF""))) ) )"),"SANGAT OPTIMAL") -> SANGAT OPTIMAL | V36: Non PLN : Genset Desa/kampung,PLTS SHS | W36: 2644 | X36: SMKN 4 BERAU | Y36: 1665000 | Z36: https://merapun-berau.desa.id/
A37: =A36+1 -> 35 | B37: BERAU | C37: KELAY | D37: MUARA LESAN | E37: KANTOR DESA | F37: 1.708500 | G37: 117.172200 | H37: BESTCAMP | I37: STARLINK | J37: Kuota FUP 100GB | K37: TERPASANG | L37: <= 50GB | M37: <= 500GB | N37: 0GB | O37: 0GB | P37: 0GB | U37: =IFERROR(__xludf.DUMMYFUNCTION("LET( angka_murni, ARRAYFORMULA(IFERROR(VALUE(REGEXREPLACE(L37:T37, ""[^0-9]"", """")), 0)), rata, IFERROR(AVERAGEIF(angka_murni, "">0""), 0), IF(rata > 0, IF(rata > 500, ""SANGAT OPTIMAL"", IF(rata > 200, ""OPTIMAL"", IF(rata > 100, "&"""KURANG OPTIMAL"", ""TIDAK OPTIMAL""))), IF(COUNTIF(L37:T37, ""*TIDAK TERDETEKSI*"") > 0, ""TIDAK TERDETEKSI"", IF(COUNTIF(L37:T37, ""*TIDAK AKTIF*"") > 0, ""TIDAK AKTIF"", IF(COUNTIF(L37:T37, ""*BELUM TERPASANG*"") > 0, ""BELUM TERPASAN"&"G"", ""TIDAK AKTIF""))) ) )"),"OPTIMAL") -> OPTIMAL | V37: Non PLN : Genset Desa/kampung,PLTS SHS | W37: 593 | X37: SMKN 4 BERAU | Y37: 2553000 | Z37: https://www.muaralesan-berau.desa.id/
A38: =A37+1 -> 36 | B38: BERAU | C38: KELAY | D38: MERASA | E38: KANTOR DESA | F38: 1.8097161662037253 | G38: 117.2386936813596 | H38: TELKOMSEL | I38: ORBIT | J38: Kuota 400Gb | K38: TERPASANG | N38: <= 100GB | O38: <= 100GB | P38: <= 100GB | Q38: <= 150GB | R38: <= 150GB | U38: =IFERROR(__xludf.DUMMYFUNCTION("LET( angka_murni, ARRAYFORMULA(IFERROR(VALUE(REGEXREPLACE(L38:T38, ""[^0-9]"", """")), 0)), rata, IFERROR(AVERAGEIF(angka_murni, "">0""), 0), IF(rata > 0, IF(rata > 500, ""SANGAT OPTIMAL"", IF(rata > 200, ""OPTIMAL"", IF(rata > 100, "&"""KURANG OPTIMAL"", ""TIDAK OPTIMAL""))), IF(COUNTIF(L38:T38, ""*TIDAK TERDETEKSI*"") > 0, ""TIDAK TERDETEKSI"", IF(COUNTIF(L38:T38, ""*TIDAK AKTIF*"") > 0, ""TIDAK AKTIF"", IF(COUNTIF(L38:T38, ""*BELUM TERPASANG*"") > 0, ""BELUM TERPASAN"&"G"", ""TIDAK AKTIF""))) ) )"),"KURANG OPTIMAL") -> KURANG OPTIMAL | V38: PLN | W38: 1104 | X38: SMKN 4 BERAU | Y38: 768950 | Z38: https://merasa-berau.desa.id/
A39: =A38+1 -> 37 | B39: BERAU | C39: KELAY | D39: LESAN DAYAK | E39: KANTOR DESA | F39: 1.6132229842246952 | G39: 117.1493566892495 | H39: COMTELINDO | I39: WMS | J39: Bandwidth 30Mbps | K39: TERPASANG | L39: <= 500GB | M39: <= 500GB | N39: <= 200GB | O39: <= 50GB | P39: <= 1GB | Q39: <= 500GB | R39: <=1000GB | U39: =IFERROR(__xludf.DUMMYFUNCTION("LET( angka_murni, ARRAYFORMULA(IFERROR(VALUE(REGEXREPLACE(L39:T39, ""[^0-9]"", """")), 0)), rata, IFERROR(AVERAGEIF(angka_murni, "">0""), 0), IF(rata > 0, IF(rata > 500, ""SANGAT OPTIMAL"", IF(rata > 200, ""OPTIMAL"", IF(rata > 100, "&"""KURANG OPTIMAL"", ""TIDAK OPTIMAL""))), IF(COUNTIF(L39:T39, ""*TIDAK TERDETEKSI*"") > 0, ""TIDAK TERDETEKSI"", IF(COUNTIF(L39:T39, ""*TIDAK AKTIF*"") > 0, ""TIDAK AKTIF"", IF(COUNTIF(L39:T39, ""*BELUM TERPASANG*"") > 0, ""BELUM TERPASAN"&"G"", ""TIDAK AKTIF""))) ) )"),"OPTIMAL") -> OPTIMAL | V39: Non PLN : Genset Desa/kampung,PLTS SHS | W39: 249 | X39: SMKN 4 BERAU | Y39: 1665000 | Z39: https://lesandayak-berau.desa.id/
A40: =A39+1 -> 38 | B40: BERAU | C40: KELAY | D40: LONG BELIU | E40: SD 001 LONG BELIU | F40: 1.715464 | G40: 117.061552 | H40: BESTCAMP | I40: STARLINK | J40: Kuota FUP 100GB | K40: TERPASANG | L40: <=1000GB | M40: <= 500GB | N40: <= 500GB | O40: <= 200GB | P40: <= 150GB | Q40: <= 100GB | U40: =IFERROR(__xludf.DUMMYFUNCTION("LET( angka_murni, ARRAYFORMULA(IFERROR(VALUE(REGEXREPLACE(L40:T40, ""[^0-9]"", """")), 0)), rata, IFERROR(AVERAGEIF(angka_murni, "">0""), 0), IF(rata > 0, IF(rata > 500, ""SANGAT OPTIMAL"", IF(rata > 200, ""OPTIMAL"", IF(rata > 100, "&"""KURANG OPTIMAL"", ""TIDAK OPTIMAL""))), IF(COUNTIF(L40:T40, ""*TIDAK TERDETEKSI*"") > 0, ""TIDAK TERDETEKSI"", IF(COUNTIF(L40:T40, ""*TIDAK AKTIF*"") > 0, ""TIDAK AKTIF"", IF(COUNTIF(L40:T40, ""*BELUM TERPASANG*"") > 0, ""BELUM TERPASAN"&"G"", ""TIDAK AKTIF""))) ) )"),"OPTIMAL") -> OPTIMAL | V40: Non PLN : WILUS PLTS TERPUSAT | W40: 930 | X40: SMKN 4 BERAU | Y40: 2553000 | Z40: https://www.longbeliu-berau.desa.id/
A41: =A40+1 -> 39 | B41: BERAU | C41: KELAY | D41: LONG DUHUNG | E41: KANTOR DESA | F41: 1.8540528929313205 | G41: 116.9542680208929 | L41: BELUM TERPASANG | M41: BELUM TERPASANG | N41: BELUM TERPASANG | O41: BELUM TERPASANG | P41: BELUM TERPASANG | U41: =IFERROR(__xludf.DUMMYFUNCTION("LET( angka_murni, ARRAYFORMULA(IFERROR(VALUE(REGEXREPLACE(L41:T41, ""[^0-9]"", """")), 0)), rata, IFERROR(AVERAGEIF(angka_murni, "">0""), 0), IF(rata > 0, IF(rata > 500, ""SANGAT OPTIMAL"", IF(rata > 200, ""OPTIMAL"", IF(rata > 100, "&"""KURANG OPTIMAL"", ""TIDAK OPTIMAL""))), IF(COUNTIF(L41:T41, ""*TIDAK TERDETEKSI*"") > 0, ""TIDAK TERDETEKSI"", IF(COUNTIF(L41:T41, ""*TIDAK AKTIF*"") > 0, ""TIDAK AKTIF"", IF(COUNTIF(L41:T41, ""*BELUM TERPASANG*"") > 0, ""BELUM TERPASAN"&"G"", ""TIDAK AKTIF""))) ) )"),"BELUM TERPASANG") -> BELUM TERPASANG | V41: Non PLN : PLTS TERPUSAT ESDM 2022 | W41: 140 | X41: SMKN 4 BERAU | Z41: https://longduhung-berau.desa.id/
...

Sheet Not Optimal
A2: NO | B2: NAMA KABUPATEN | C2: NAMA KECAMATAN | D2: NAMA DESA | E2: TITIK PEMASANGAN | F2: KOORDINAT LINTANG | G2: KOORDINAT BUJUR | H2: ISP | I2: PRODUK | J2: STATUS | K2: JANUARI | L2: FEBRUARI | M2: MARET | N2: APRIL | O2: MEI | P2: HASIL EVALUASI | Q2: NAMA PIC | R2: KONTAK PC | S2: TINDAK LANJUT | T2: KENDALA | U2: LISTRIK | V2: JUMLAH PENDUDUK (JIWA) | W2: SMA/SMK | X2: BIAYA BULANAN | Y2: LINK
A3: 1 | B3: BERAU | C3: BATU PUTIH | D3: SUMBER AGUNG | E3: KANTOR DESA | F3: 1.4578195365757132 | G3: 118.31199995866533 | H3: TELKOMSEL | I3: ORBIT | J3: TERPASANG | M3: TIDAK AKTIF | N3: TIDAK AKTIF | O3: TIDAK AKTIF | P3: =IFERROR(__xludf.DUMMYFUNCTION("LET( angka_murni, ARRAYFORMULA(IFERROR(VALUE(REGEXREPLACE(K3:O3, ""[^0-9]"", """")), 0)), rata, IFERROR(AVERAGEIF(angka_murni, "">0""), 0), IF(rata > 0, IF(rata > 500, ""SANGAT OPTIMAL"", IF(rata > 200, ""OPTIMAL"", IF(rata > 100, ""K"&"URANG OPTIMAL"", ""TIDAK OPTIMAL""))), IF(COUNTIF(K3:O3, ""*TIDAK TERDETEKSI*"") > 0, ""TIDAK TERDETEKSI"", IF(COUNTIF(K3:O3, ""*TIDAK AKTIF*"") > 0, ""TIDAK AKTIF"", IF(COUNTIF(K3:O3, ""*BELUM TERPASANG*"") > 0, ""BELUM TERPASANG"", ""TI"&"DAK AKTIF""))) ) )"),"TIDAK AKTIF") -> TIDAK AKTIF | Q3: Masdi, S.Pd | R3: 0821 5493 1067 | U3: PLN | V3: 829 | W3: SMAN 10 BERAU | X3: 768950 | Y3: https://sumberagung.digitaldesa.id/
A4: =A3+1 -> 2 | B4: BERAU | C4: KELAY | D4: MUARA LESAN | E4: KANTOR DESA | F4: 1.708500 | G4: 117.172200 | H4: BESTCAMP | I4: STARLINK | J4: TERPASANG | K4: <= 50GB | L4: <= 500GB | M4: TIDAK AKTIF | N4: TIDAK AKTIF | O4: TIDAK AKTIF | P4: =IFERROR(__xludf.DUMMYFUNCTION("LET( angka_murni, ARRAYFORMULA(IFERROR(VALUE(REGEXREPLACE(K4:O4, ""[^0-9]"", """")), 0)), rata, IFERROR(AVERAGEIF(angka_murni, "">0""), 0), IF(rata > 0, IF(rata > 500, ""SANGAT OPTIMAL"", IF(rata > 200, ""OPTIMAL"", IF(rata > 100, ""K"&"URANG OPTIMAL"", ""TIDAK OPTIMAL""))), IF(COUNTIF(K4:O4, ""*TIDAK TERDETEKSI*"") > 0, ""TIDAK TERDETEKSI"", IF(COUNTIF(K4:O4, ""*TIDAK AKTIF*"") > 0, ""TIDAK AKTIF"", IF(COUNTIF(K4:O4, ""*BELUM TERPASANG*"") > 0, ""BELUM TERPASANG"", ""TI"&"DAK AKTIF""))) ) )"),"OPTIMAL") -> OPTIMAL | U4: Non PLN : Genset Desa/kampung,PLTS SHS | V4: 593 | W4: SMKN 4 BERAU | X4: 2553000 | Y4: https://www.muaralesan-berau.desa.id/
A5: =A4+1 -> 3 | B5: BERAU | C5: MARATUA | D5: PAYUNG-PAYUNG | E5: KANTOR DESA | F5: 2.1957777536222016 | G5: 118.5974885708768 | H5: TELKOMSEL | I5: ORBIT | J5: TERPASANG | M5: TIDAK AKTIF | N5: TIDAK AKTIF | O5: TIDAK AKTIF | P5: =IFERROR(__xludf.DUMMYFUNCTION("LET( angka_murni, ARRAYFORMULA(IFERROR(VALUE(REGEXREPLACE(K5:O5, ""[^0-9]"", """")), 0)), rata, IFERROR(AVERAGEIF(angka_murni, "">0""), 0), IF(rata > 0, IF(rata > 500, ""SANGAT OPTIMAL"", IF(rata > 200, ""OPTIMAL"", IF(rata > 100, ""K"&"URANG OPTIMAL"", ""TIDAK OPTIMAL""))), IF(COUNTIF(K5:O5, ""*TIDAK TERDETEKSI*"") > 0, ""TIDAK TERDETEKSI"", IF(COUNTIF(K5:O5, ""*TIDAK AKTIF*"") > 0, ""TIDAK AKTIF"", IF(COUNTIF(K5:O5, ""*BELUM TERPASANG*"") > 0, ""BELUM TERPASANG"", ""TI"&"DAK AKTIF""))) ) )"),"TIDAK AKTIF") -> TIDAK AKTIF | Q5: Rico | R5: 0813 4161 1564 | U5: PLN | V5: 797 | W5: SMAN 9 BERAU | X5: 768950
A6: =A5+1 -> 4 | B6: BERAU | C6: MARATUA | D6: TELUK HARAPAN | E6: KANTOR DESA | F6: 2.2482914307667574 | G6: 118.56399702121716 | H6: TELKOMSEL | I6: ORBIT | J6: TERPASANG | M6: TIDAK AKTIF | N6: TIDAK AKTIF | O6: TIDAK AKTIF | P6: =IFERROR(__xludf.DUMMYFUNCTION("LET( angka_murni, ARRAYFORMULA(IFERROR(VALUE(REGEXREPLACE(K6:O6, ""[^0-9]"", """")), 0)), rata, IFERROR(AVERAGEIF(angka_murni, "">0""), 0), IF(rata > 0, IF(rata > 500, ""SANGAT OPTIMAL"", IF(rata > 200, ""OPTIMAL"", IF(rata > 100, ""K"&"URANG OPTIMAL"", ""TIDAK OPTIMAL""))), IF(COUNTIF(K6:O6, ""*TIDAK TERDETEKSI*"") > 0, ""TIDAK TERDETEKSI"", IF(COUNTIF(K6:O6, ""*TIDAK AKTIF*"") > 0, ""TIDAK AKTIF"", IF(COUNTIF(K6:O6, ""*BELUM TERPASANG*"") > 0, ""BELUM TERPASANG"", ""TI"&"DAK AKTIF""))) ) )"),"TIDAK AKTIF") -> TIDAK AKTIF | Q6: Abnir Dani Lupi | R6: 0852 1779 2577 | U6: PLN | V6: 1284 | W6: SMAN 9 BERAU | X6: 768950 | Y6: https://telukharapan.id/
A7: =A6+1 -> 5 | B7: BERAU | C7: SEGAH | D7: PUNAN SEGAH | E7: KANTOR DESA | F7: 2.3764425889855696 | G7: 116.65596483779778 | H7: COMTELINDO | I7: WMS | J7: TERPASANG | K7: <= 150GB | L7: <= 50GB | M7: TIDAK AKTIF | N7: <= 150GB | O7: TIDAK AKTIF | P7: =IFERROR(__xludf.DUMMYFUNCTION("LET( angka_murni, ARRAYFORMULA(IFERROR(VALUE(REGEXREPLACE(K7:O7, ""[^0-9]"", """")), 0)), rata, IFERROR(AVERAGEIF(angka_murni, "">0""), 0), IF(rata > 0, IF(rata > 500, ""SANGAT OPTIMAL"", IF(rata > 200, ""OPTIMAL"", IF(rata > 100, ""K"&"URANG OPTIMAL"", ""TIDAK OPTIMAL""))), IF(COUNTIF(K7:O7, ""*TIDAK TERDETEKSI*"") > 0, ""TIDAK TERDETEKSI"", IF(COUNTIF(K7:O7, ""*TIDAK AKTIF*"") > 0, ""TIDAK AKTIF"", IF(COUNTIF(K7:O7, ""*BELUM TERPASANG*"") > 0, ""BELUM TERPASANG"", ""TI"&"DAK AKTIF""))) ) )"),"KURANG OPTIMAL") -> KURANG OPTIMAL | U7: Non PLN : Genset Desa/kampung,PLTS SHS | V7: 128 | W7: SMK NEGERI 5 BERAU | X7: 1665000
A8: =A7+1 -> 6 | B8: BERAU | C8: SEGAH | D8: PANDAN SARI | E8: KANTOR DESA | F8: 2.0774877630806916 | G8: 117.234147339748 | H8: TELKOMSEL | I8: ORBIT | J8: TERPASANG | M8: TIDAK AKTIF | N8: TIDAK AKTIF | O8: TIDAK AKTIF | P8: =IFERROR(__xludf.DUMMYFUNCTION("LET( angka_murni, ARRAYFORMULA(IFERROR(VALUE(REGEXREPLACE(K8:O8, ""[^0-9]"", """")), 0)), rata, IFERROR(AVERAGEIF(angka_murni, "">0""), 0), IF(rata > 0, IF(rata > 500, ""SANGAT OPTIMAL"", IF(rata > 200, ""OPTIMAL"", IF(rata > 100, ""K"&"URANG OPTIMAL"", ""TIDAK OPTIMAL""))), IF(COUNTIF(K8:O8, ""*TIDAK TERDETEKSI*"") > 0, ""TIDAK TERDETEKSI"", IF(COUNTIF(K8:O8, ""*TIDAK AKTIF*"") > 0, ""TIDAK AKTIF"", IF(COUNTIF(K8:O8, ""*BELUM TERPASANG*"") > 0, ""BELUM TERPASANG"", ""TI"&"DAK AKTIF""))) ) )"),"TIDAK AKTIF") -> TIDAK AKTIF | Q8: Ujang Ungau | R8: 0852 4701 2249 | U8: PLN | V8: 1422 | W8: SMK NEGERI 5 BERAU | X8: 768950 | Y8: https://desa-pandansari.id/
A9: =A8+1 -> 7 | B9: BERAU | C9: TABALAR | D9: TABALAR MUARA | E9: KANTOR DESA | F9: 1.7551738488066142 | G9: 117.97345249976799 | H9: TELKOMSEL | I9: ORBIT | J9: TERPASANG | M9: TIDAK AKTIF | N9: TIDAK AKTIF | O9: TIDAK AKTIF | P9: =IFERROR(__xludf.DUMMYFUNCTION("LET( angka_murni, ARRAYFORMULA(IFERROR(VALUE(REGEXREPLACE(K9:O9, ""[^0-9]"", """")), 0)), rata, IFERROR(AVERAGEIF(angka_murni, "">0""), 0), IF(rata > 0, IF(rata > 500, ""SANGAT OPTIMAL"", IF(rata > 200, ""OPTIMAL"", IF(rata > 100, ""K"&"URANG OPTIMAL"", ""TIDAK OPTIMAL""))), IF(COUNTIF(K9:O9, ""*TIDAK TERDETEKSI*"") > 0, ""TIDAK TERDETEKSI"", IF(COUNTIF(K9:O9, ""*TIDAK AKTIF*"") > 0, ""TIDAK AKTIF"", IF(COUNTIF(K9:O9, ""*BELUM TERPASANG*"") > 0, ""BELUM TERPASANG"", ""TI"&"DAK AKTIF""))) ) )"),"TIDAK AKTIF") -> TIDAK AKTIF | Q9: Frisnar Paysal | R9: 0852 4677 9059 | U9: PLN | V9: 1052 | W9: SMK NEGERI 7 BERAU | X9: 768950
A10: =A9+1 -> 8 | B10: BERAU | C10: TABALAR | D10: HARAPAN MAJU | E10: KANTOR DESA | F10: 1.7162356801101053 | G10: 117.96059472866186 | H10: TELKOMSEL | I10: ORBIT | J10: TERPASANG | M10: TIDAK AKTIF | N10: TIDAK AKTIF | O10: TIDAK AKTIF | P10: =IFERROR(__xludf.DUMMYFUNCTION("LET( angka_murni, ARRAYFORMULA(IFERROR(VALUE(REGEXREPLACE(K10:O10, ""[^0-9]"", """")), 0)), rata, IFERROR(AVERAGEIF(angka_murni, "">0""), 0), IF(rata > 0, IF(rata > 500, ""SANGAT OPTIMAL"", IF(rata > 200, ""OPTIMAL"", IF(rata > 100, "&"""KURANG OPTIMAL"", ""TIDAK OPTIMAL""))), IF(COUNTIF(K10:O10, ""*TIDAK TERDETEKSI*"") > 0, ""TIDAK TERDETEKSI"", IF(COUNTIF(K10:O10, ""*TIDAK AKTIF*"") > 0, ""TIDAK AKTIF"", IF(COUNTIF(K10:O10, ""*BELUM TERPASANG*"") > 0, ""BELUM TERPASAN"&"G"", ""TIDAK AKTIF""))) ) )"),"TIDAK AKTIF") -> TIDAK AKTIF | Q10: Hamzah | R10: 0822 5392 9779 | U10: PLN | V10: 1164 | W10: SMK NEGERI 7 BERAU | X10: 768950
A11: =A10+1 -> 9 | B11: BERAU | C11: TALISAYAN | D11: SUKA MURYA | E11: KANTOR DESA | F11: 1.5682111757449444 | G11: 118.16108497319644 | H11: TELKOMSEL | I11: ORBIT | J11: TERPASANG | M11: TIDAK AKTIF | N11: TIDAK AKTIF | O11: TIDAK AKTIF | P11: =IFERROR(__xludf.DUMMYFUNCTION("LET( angka_murni, ARRAYFORMULA(IFERROR(VALUE(REGEXREPLACE(K11:O11, ""[^0-9]"", """")), 0)), rata, IFERROR(AVERAGEIF(angka_murni, "">0""), 0), IF(rata > 0, IF(rata > 500, ""SANGAT OPTIMAL"", IF(rata > 200, ""OPTIMAL"", IF(rata > 100, "&"""KURANG OPTIMAL"", ""TIDAK OPTIMAL""))), IF(COUNTIF(K11:O11, ""*TIDAK TERDETEKSI*"") > 0, ""TIDAK TERDETEKSI"", IF(COUNTIF(K11:O11, ""*TIDAK AKTIF*"") > 0, ""TIDAK AKTIF"", IF(COUNTIF(K11:O11, ""*BELUM TERPASANG*"") > 0, ""BELUM TERPASAN"&"G"", ""TIDAK AKTIF""))) ) )"),"TIDAK AKTIF") -> TIDAK AKTIF | Q11: Poldi, A.Ma.Pd.S.D. | R11: 0821 5455 9188 | U11: PLN | V11: 1310 | W11: SMK NEGERI 8, SMAN 3, SMAN 11 & SMAN 13 BERAU | X11: 768950
A12: =A11+1 -> 10 | B12: KUTAI BARAT | C12: BENTIAN BESAR | D12: JELMU SIBAK | E12: KANTOR DESA | F12: -0.8786543998607228 | G12: 115.7456375291888 | H12: TELKOMSEL | I12: ORBIT | J12: TERPASANG | M12: TIDAK AKTIF | N12: TIDAK AKTIF | O12: TIDAK AKTIF | P12: =IFERROR(__xludf.DUMMYFUNCTION("LET( angka_murni, ARRAYFORMULA(IFERROR(VALUE(REGEXREPLACE(K12:O12, ""[^0-9]"", """")), 0)), rata, IFERROR(AVERAGEIF(angka_murni, "">0""), 0), IF(rata > 0, IF(rata > 500, ""SANGAT OPTIMAL"", IF(rata > 200, ""OPTIMAL"", IF(rata > 100, "&"""KURANG OPTIMAL"", ""TIDAK OPTIMAL""))), IF(COUNTIF(K12:O12, ""*TIDAK TERDETEKSI*"") > 0, ""TIDAK TERDETEKSI"", IF(COUNTIF(K12:O12, ""*TIDAK AKTIF*"") > 0, ""TIDAK AKTIF"", IF(COUNTIF(K12:O12, ""*BELUM TERPASANG*"") > 0, ""BELUM TERPASAN"&"G"", ""TIDAK AKTIF""))) ) )"),"TIDAK AKTIF") -> TIDAK AKTIF | Q12: Sakastian | R12: 0823 5750 2325 | U12: Non PLN : Genset Desa/kampung,PLTS SHS | V12: 528 | W12: SMAN 1 BENTIAN BESAR | X12: 768950
A13: =A12+1 -> 11 | B13: KUTAI BARAT | C13: BONGAN | D13: MUARA SIRAM | E13: KANTOR DESA | F13: -0.7477491579546033 | G13: 116.17935450017545 | H13: TELKOMSEL | I13: ORBIT | J13: TERPASANG | M13: TIDAK AKTIF | N13: TIDAK AKTIF | O13: TIDAK AKTIF | P13: =IFERROR(__xludf.DUMMYFUNCTION("LET( angka_murni, ARRAYFORMULA(IFERROR(VALUE(REGEXREPLACE(K13:O13, ""[^0-9]"", """")), 0)), rata, IFERROR(AVERAGEIF(angka_murni, "">0""), 0), IF(rata > 0, IF(rata > 500, ""SANGAT OPTIMAL"", IF(rata > 200, ""OPTIMAL"", IF(rata > 100, "&"""KURANG OPTIMAL"", ""TIDAK OPTIMAL""))), IF(COUNTIF(K13:O13, ""*TIDAK TERDETEKSI*"") > 0, ""TIDAK TERDETEKSI"", IF(COUNTIF(K13:O13, ""*TIDAK AKTIF*"") > 0, ""TIDAK AKTIF"", IF(COUNTIF(K13:O13, ""*BELUM TERPASANG*"") > 0, ""BELUM TERPASAN"&"G"", ""TIDAK AKTIF""))) ) )"),"TIDAK AKTIF") -> TIDAK AKTIF | Q13: Ardian | R13: 0815 4515 7476 | U13: PLN | V13: 964 | W13: SMKN 1 & SMAN 1 BONGAN | X13: 768950
A14: =A13+1 -> 12 | B14: KUTAI BARAT | C14: MOOK MANAAR BULATN | D14: MERAYAQ | E14: KANTOR DESA | F14: -0.13742964991336454 | G14: 115.8160478903606 | H14: COMTELINDO | I14: WMS | J14: TERPASANG | K14: TIDAK AKTIF | L14: TIDAK AKTIF | M14: TIDAK AKTIF | N14: <= 10GB | O14: TIDAK AKTIF | P14: =IFERROR(__xludf.DUMMYFUNCTION("LET( angka_murni, ARRAYFORMULA(IFERROR(VALUE(REGEXREPLACE(K14:O14, ""[^0-9]"", """")), 0)), rata, IFERROR(AVERAGEIF(angka_murni, "">0""), 0), IF(rata > 0, IF(rata > 500, ""SANGAT OPTIMAL"", IF(rata > 200, ""OPTIMAL"", IF(rata > 100, "&"""KURANG OPTIMAL"", ""TIDAK OPTIMAL""))), IF(COUNTIF(K14:O14, ""*TIDAK TERDETEKSI*"") > 0, ""TIDAK TERDETEKSI"", IF(COUNTIF(K14:O14, ""*TIDAK AKTIF*"") > 0, ""TIDAK AKTIF"", IF(COUNTIF(K14:O14, ""*BELUM TERPASANG*"") > 0, ""BELUM TERPASAN"&"G"", ""TIDAK AKTIF""))) ) )"),"TIDAK OPTIMAL") -> TIDAK OPTIMAL | U14: PLN | V14: 244 | W14: SMKN 1 & SMAN 1 MOOK MANAAR BULATN | X14: 1665000
A15: =A14+1 -> 13 | B15: KUTAI BARAT | C15: MOOK MANAAR BULATN | D15: LINGGANG MARIMUN | E15: KANTOR DESA | F15: -0.07297415753918389 | G15: 115.773775213154 | H15: COMTELINDO | I15: WMS | J15: TERPASANG | K15: TIDAK TERDETEKSI | L15: TIDAK TERDETEKSI | M15: TIDAK TERDETEKSI | N15: TIDAK TERDETEKSI | O15: TIDAK TERDETEKSI | P15: =IFERROR(__xludf.DUMMYFUNCTION("LET( angka_murni, ARRAYFORMULA(IFERROR(VALUE(REGEXREPLACE(K15:O15, ""[^0-9]"", """")), 0)), rata, IFERROR(AVERAGEIF(angka_murni, "">0""), 0), IF(rata > 0, IF(rata > 500, ""SANGAT OPTIMAL"", IF(rata > 200, ""OPTIMAL"", IF(rata > 100, "&"""KURANG OPTIMAL"", ""TIDAK OPTIMAL""))), IF(COUNTIF(K15:O15, ""*TIDAK TERDETEKSI*"") > 0, ""TIDAK TERDETEKSI"", IF(COUNTIF(K15:O15, ""*TIDAK AKTIF*"") > 0, ""TIDAK AKTIF"", IF(COUNTIF(K15:O15, ""*BELUM TERPASANG*"") > 0, ""BELUM TERPASAN"&"G"", ""TIDAK AKTIF""))) ) )"),"TIDAK TERDETEKSI") -> TIDAK TERDETEKSI | U15: Non PLN : Genset Desa/kampung,PLTS SHS | V15: 1021 | W15: SMKN 1 & SMAN 1 MOOK MANAAR BULATN | X15: 1665000
A16: =A15+1 -> 14 | B16: KUTAI BARAT | C16: MOOK MANAAR BULATN | D16: GADUR | E16: KANTOR DESA | F16: -0.27041735941823736 | G16: 115.90284173841835 | H16: COMTELINDO | I16: WMS | J16: TERPASANG | K16: TIDAK AKTIF | L16: TIDAK AKTIF | M16: TIDAK AKTIF | N16: TIDAK AKTIF | O16: TIDAK AKTIF | P16: =IFERROR(__xludf.DUMMYFUNCTION("LET( angka_murni, ARRAYFORMULA(IFERROR(VALUE(REGEXREPLACE(K16:O16, ""[^0-9]"", """")), 0)), rata, IFERROR(AVERAGEIF(angka_murni, "">0""), 0), IF(rata > 0, IF(rata > 500, ""SANGAT OPTIMAL"", IF(rata > 200, ""OPTIMAL"", IF(rata > 100, "&"""KURANG OPTIMAL"", ""TIDAK OPTIMAL""))), IF(COUNTIF(K16:O16, ""*TIDAK TERDETEKSI*"") > 0, ""TIDAK TERDETEKSI"", IF(COUNTIF(K16:O16, ""*TIDAK AKTIF*"") > 0, ""TIDAK AKTIF"", IF(COUNTIF(K16:O16, ""*BELUM TERPASANG*"") > 0, ""BELUM TERPASAN"&"G"", ""TIDAK AKTIF""))) ) )"),"TIDAK AKTIF") -> TIDAK AKTIF | U16: PLN | V16: 391 | W16: SMKN 1 & SMAN 1 MOOK MANAAR BULATN | X16: 1665000 | Y16: https://gadur.nusadesa.id//
A17: =A16+1 -> 15 | B17: KUTAI BARAT | C17: MOOK MANAAR BULATN | D17: MUARA KALAQ | E17: KANTOR DESA | F17: -0.1034398256484514 | G17: 115.77321482065024 | H17: COMTELINDO | I17: WMS | J17: TERPASANG | K17: TIDAK TERDETEKSI | L17: TIDAK TERDETEKSI | M17: TIDAK TERDETEKSI | N17: TIDAK TERDETEKSI | O17: TIDAK TERDETEKSI | P17: =IFERROR(__xludf.DUMMYFUNCTION("LET( angka_murni, ARRAYFORMULA(IFERROR(VALUE(REGEXREPLACE(K17:O17, ""[^0-9]"", """")), 0)), rata, IFERROR(AVERAGEIF(angka_murni, "">0""), 0), IF(rata > 0, IF(rata > 500, ""SANGAT OPTIMAL"", IF(rata > 200, ""OPTIMAL"", IF(rata > 100, "&"""KURANG OPTIMAL"", ""TIDAK OPTIMAL""))), IF(COUNTIF(K17:O17, ""*TIDAK TERDETEKSI*"") > 0, ""TIDAK TERDETEKSI"", IF(COUNTIF(K17:O17, ""*TIDAK AKTIF*"") > 0, ""TIDAK AKTIF"", IF(COUNTIF(K17:O17, ""*BELUM TERPASANG*"") > 0, ""BELUM TERPASAN"&"G"", ""TIDAK AKTIF""))) ) )"),"TIDAK TERDETEKSI") -> TIDAK TERDETEKSI | U17: Non PLN : Genset Desa/kampung,PLTS SHS | V17: 216 | W17: SMKN 1 & SMAN 1 MOOK MANAAR BULATN | X17: 1665000 | Y17: https://kampungmuarakalaq.id/
A18: =A17+1 -> 16 | B18: KUTAI BARAT | C18: MUARA LAWA | D18: MUARA BEGAI | E18: KANTOR DESA | F18: -0.5837256067032629 | G18: 115.71010773336087 | H18: TELKOMSEL | I18: ORBIT | J18: TERPASANG | M18: TIDAK AKTIF | N18: TIDAK AKTIF | O18: TIDAK AKTIF | P18: =IFERROR(__xludf.DUMMYFUNCTION("LET( angka_murni, ARRAYFORMULA(IFERROR(VALUE(REGEXREPLACE(K18:O18, ""[^0-9]"", """")), 0)), rata, IFERROR(AVERAGEIF(angka_murni, "">0""), 0), IF(rata > 0, IF(rata > 500, ""SANGAT OPTIMAL"", IF(rata > 200, ""OPTIMAL"", IF(rata > 100, "&"""KURANG OPTIMAL"", ""TIDAK OPTIMAL""))), IF(COUNTIF(K18:O18, ""*TIDAK TERDETEKSI*"") > 0, ""TIDAK TERDETEKSI"", IF(COUNTIF(K18:O18, ""*TIDAK AKTIF*"") > 0, ""TIDAK AKTIF"", IF(COUNTIF(K18:O18, ""*BELUM TERPASANG*"") > 0, ""BELUM TERPASAN"&"G"", ""TIDAK AKTIF""))) ) )"),"TIDAK AKTIF") -> TIDAK AKTIF | Q18: Antonius. P | R18: 0813 5020 1670 | U18: PLN | V18: 8196 | W18: SMAN 1 MUARA LAWA | X18: 768950
A19: =A18+1 -> 17 | B19: KUTAI BARAT | C19: MUARA LAWA | D19: DINGIN | E19: KANTOR DESA | F19: -0.47642520711286424 | G19: 115.79760301834777 | H19: BESTCAMP | I19: STARLINK | J19: TERPASANG | K19: <= 10GB | L19: TIDAK AKTIF | M19: TIDAK AKTIF | N19: TIDAK AKTIF | O19: TIDAK AKTIF | P19: =IFERROR(__xludf.DUMMYFUNCTION("LET( angka_murni, ARRAYFORMULA(IFERROR(VALUE(REGEXREPLACE(K19:O19, ""[^0-9]"", """")), 0)), rata, IFERROR(AVERAGEIF(angka_murni, "">0""), 0), IF(rata > 0, IF(rata > 500, ""SANGAT OPTIMAL"", IF(rata > 200, ""OPTIMAL"", IF(rata > 100, "&"""KURANG OPTIMAL"", ""TIDAK OPTIMAL""))), IF(COUNTIF(K19:O19, ""*TIDAK TERDETEKSI*"") > 0, ""TIDAK TERDETEKSI"", IF(COUNTIF(K19:O19, ""*TIDAK AKTIF*"") > 0, ""TIDAK AKTIF"", IF(COUNTIF(K19:O19, ""*BELUM TERPASANG*"") > 0, ""BELUM TERPASAN"&"G"", ""TIDAK AKTIF""))) ) )"),"TIDAK OPTIMAL") -> TIDAK OPTIMAL | U19: PLN | V19: 1083 | W19: SMAN 1 MUARA LAWA | X19: 2553000
A20: =A19+1 -> 18 | B20: KUTAI BARAT | C20: PENYINGGAHAN | D20: PENYINGGAHAN ULU | E20: KANTOR DESA | F20: -0.3807539285053537 | G20: 116.22152399970584 | H20: TELKOMSEL | I20: ORBIT | J20: TERPASANG | M20: TIDAK AKTIF | N20: TIDAK AKTIF | O20: TIDAK AKTIF | P20: =IFERROR(__xludf.DUMMYFUNCTION("LET( angka_murni, ARRAYFORMULA(IFERROR(VALUE(REGEXREPLACE(K20:O20, ""[^0-9]"", """")), 0)), rata, IFERROR(AVERAGEIF(angka_murni, "">0""), 0), IF(rata > 0, IF(rata > 500, ""SANGAT OPTIMAL"", IF(rata > 200, ""OPTIMAL"", IF(rata > 100, "&"""KURANG OPTIMAL"", ""TIDAK OPTIMAL""))), IF(COUNTIF(K20:O20, ""*TIDAK TERDETEKSI*"") > 0, ""TIDAK TERDETEKSI"", IF(COUNTIF(K20:O20, ""*TIDAK AKTIF*"") > 0, ""TIDAK AKTIF"", IF(COUNTIF(K20:O20, ""*BELUM TERPASANG*"") > 0, ""BELUM TERPASAN"&"G"", ""TIDAK AKTIF""))) ) )"),"TIDAK AKTIF") -> TIDAK AKTIF | Q20: Kusnadi | R20: 0821 5421 6271 | U20: PLN | V20: 941 | W20: SMAN 1 PENYINGGAHAN | X20: 768950
A21: =A20+1 -> 19 | B21: KUTAI KARTANEGARA | C21: ANGGANA | D21: SUNGAI MERIAM | E21: KANTOR DESA | F21: -0.571 | G21: 117.265 | H21: TELKOMSEL | I21: INDIHOME | J21: TERPASANG | K21: TIDAK AKTIF | L21: TIDAK AKTIF | M21: TIDAK AKTIF | N21: TIDAK AKTIF | O21: TIDAK AKTIF | P21: =IFERROR(__xludf.DUMMYFUNCTION("LET( angka_murni, ARRAYFORMULA(IFERROR(VALUE(REGEXREPLACE(K21:O21, ""[^0-9]"", """")), 0)), rata, IFERROR(AVERAGEIF(angka_murni, "">0""), 0), IF(rata > 0, IF(rata > 500, ""SANGAT OPTIMAL"", IF(rata > 200, ""OPTIMAL"", IF(rata > 100, "&"""KURANG OPTIMAL"", ""TIDAK OPTIMAL""))), IF(COUNTIF(K21:O21, ""*TIDAK TERDETEKSI*"") > 0, ""TIDAK TERDETEKSI"", IF(COUNTIF(K21:O21, ""*TIDAK AKTIF*"") > 0, ""TIDAK AKTIF"", IF(COUNTIF(K21:O21, ""*BELUM TERPASANG*"") > 0, ""BELUM TERPASAN"&"G"", ""TIDAK AKTIF""))) ) )"),"TIDAK AKTIF") -> TIDAK AKTIF | U21: PLN | V21: 12121 | W21: SMKN 1 & SMAN 1 ANGGANA | X21: 604950 | Y21: Sungai Meriam
A22: =A21+1 -> 20 | B22: KUTAI KARTANEGARA | C22: KEMBANG JANGGUT | D22: LONG BELEH MODANG | E22: KANTOR DESA | F22: 0.3322653059261473 | G22: 116.16006289423218 | H22: TELKOMSEL | I22: ORBIT | J22: TERPASANG | M22: TIDAK AKTIF | N22: TIDAK AKTIF | O22: TIDAK AKTIF | P22: =IFERROR(__xludf.DUMMYFUNCTION("LET( angka_murni, ARRAYFORMULA(IFERROR(VALUE(REGEXREPLACE(K22:O22, ""[^0-9]"", """")), 0)), rata, IFERROR(AVERAGEIF(angka_murni, "">0""), 0), IF(rata > 0, IF(rata > 500, ""SANGAT OPTIMAL"", IF(rata > 200, ""OPTIMAL"", IF(rata > 100, "&"""KURANG OPTIMAL"", ""TIDAK OPTIMAL""))), IF(COUNTIF(K22:O22, ""*TIDAK TERDETEKSI*"") > 0, ""TIDAK TERDETEKSI"", IF(COUNTIF(K22:O22, ""*TIDAK AKTIF*"") > 0, ""TIDAK AKTIF"", IF(COUNTIF(K22:O22, ""*BELUM TERPASANG*"") > 0, ""BELUM TERPASAN"&"G"", ""TIDAK AKTIF""))) ) )"),"TIDAK AKTIF") -> TIDAK AKTIF | Q22: Amsar Bin Harun Sihotang | R22: 0852 3322 6200 | U22: PLN | V22: 3250 | W22: SMKN 1 & SMAN 1 KEMBANG JANGGUT | X22: 768950
A23: =A22+1 -> 21 | B23: KUTAI KARTANEGARA | C23: KEMBANG JANGGUT | D23: MUAI | E23: KANTOR DESA | F23: 0.29312408765161524 | G23: 116.1937070658113 | H23: TELKOMSEL | I23: ORBIT | J23: TERPASANG | M23: TIDAK AKTIF | N23: TIDAK AKTIF | O23: TIDAK AKTIF | P23: =IFERROR(__xludf.DUMMYFUNCTION("LET( angka_murni, ARRAYFORMULA(IFERROR(VALUE(REGEXREPLACE(K23:O23, ""[^0-9]"", """")), 0)), rata, IFERROR(AVERAGEIF(angka_murni, "">0""), 0), IF(rata > 0, IF(rata > 500, ""SANGAT OPTIMAL"", IF(rata > 200, ""OPTIMAL"", IF(rata > 100, "&"""KURANG OPTIMAL"", ""TIDAK OPTIMAL""))), IF(COUNTIF(K23:O23, ""*TIDAK TERDETEKSI*"") > 0, ""TIDAK TERDETEKSI"", IF(COUNTIF(K23:O23, ""*TIDAK AKTIF*"") > 0, ""TIDAK AKTIF"", IF(COUNTIF(K23:O23, ""*BELUM TERPASANG*"") > 0, ""BELUM TERPASAN"&"G"", ""TIDAK AKTIF""))) ) )"),"TIDAK AKTIF") -> TIDAK AKTIF | Q23: Ali Husni | R23: 0812 5749 7446 | U23: PLN | V23: 2109 | W23: SMKN 1 & SMAN 1 KEMBANG JANGGUT | X23: 768950
A24: =A23+1 -> 22 | B24: KUTAI KARTANEGARA | C24: LOA KULU | D24: JEMBAYAN | E24: KANTOR DESA | F24: -0.552 | G24: 117.020 | H24: TELKOMSEL | I24: INDIHOME | J24: TERPASANG | K24: <= 500GB | L24: <= 500GB | M24: TIDAK AKTIF | N24: TIDAK AKTIF | O24: TIDAK AKTIF | P24: =IFERROR(__xludf.DUMMYFUNCTION("LET( angka_murni, ARRAYFORMULA(IFERROR(VALUE(REGEXREPLACE(K24:O24, ""[^0-9]"", """")), 0)), rata, IFERROR(AVERAGEIF(angka_murni, "">0""), 0), IF(rata > 0, IF(rata > 500, ""SANGAT OPTIMAL"", IF(rata > 200, ""OPTIMAL"", IF(rata > 100, "&"""KURANG OPTIMAL"", ""TIDAK OPTIMAL""))), IF(COUNTIF(K24:O24, ""*TIDAK TERDETEKSI*"") > 0, ""TIDAK TERDETEKSI"", IF(COUNTIF(K24:O24, ""*TIDAK AKTIF*"") > 0, ""TIDAK AKTIF"", IF(COUNTIF(K24:O24, ""*BELUM TERPASANG*"") > 0, ""BELUM TERPASAN"&"G"", ""TIDAK AKTIF""))) ) )"),"OPTIMAL") -> OPTIMAL | U24: PLN | V24: 5230 | W24: SMAN 1, SMAN 2 & SMKN 3 LOA KULU | X24: 604950
A25: =A24+1 -> 23 | B25: KUTAI KARTANEGARA | C25: LOA KULU | D25: JONGKANG | E25: KANTOR DESA | F25: -0.462 | G25: 117.021 | H25: TELKOMSEL | I25: INDIHOME | J25: TERPASANG | K25: TIDAK AKTIF | L25: TIDAK AKTIF | M25: TIDAK AKTIF | N25: TIDAK AKTIF | O25: TIDAK AKTIF | P25: =IFERROR(__xludf.DUMMYFUNCTION("LET( angka_murni, ARRAYFORMULA(IFERROR(VALUE(REGEXREPLACE(K25:O25, ""[^0-9]"", """")), 0)), rata, IFERROR(AVERAGEIF(angka_murni, "">0""), 0), IF(rata > 0, IF(rata > 500, ""SANGAT OPTIMAL"", IF(rata > 200, ""OPTIMAL"", IF(rata > 100, "&"""KURANG OPTIMAL"", ""TIDAK OPTIMAL""))), IF(COUNTIF(K25:O25, ""*TIDAK TERDETEKSI*"") > 0, ""TIDAK TERDETEKSI"", IF(COUNTIF(K25:O25, ""*TIDAK AKTIF*"") > 0, ""TIDAK AKTIF"", IF(COUNTIF(K25:O25, ""*BELUM TERPASANG*"") > 0, ""BELUM TERPASAN"&"G"", ""TIDAK AKTIF""))) ) )"),"TIDAK AKTIF") -> TIDAK AKTIF | U25: PLN | V25: 3524 | W25: SMAN 1, SMAN 2 & SMKN 3 LOA KULU | X25: 604950
A26: =A25+1 -> 24 | B26: KUTAI KARTANEGARA | C26: MUARA BADAK | D26: TANJUNG LIMAU | E26: KANTOR DESA | F26: -0.301 | G26: 117.442 | H26: TELKOMSEL | I26: INDIHOME | J26: TERPASANG | K26: TIDAK AKTIF | L26: TIDAK AKTIF | M26: TIDAK AKTIF | N26: TIDAK AKTIF | O26: TIDAK AKTIF | P26: =IFERROR(__xludf.DUMMYFUNCTION("LET( angka_murni, ARRAYFORMULA(IFERROR(VALUE(REGEXREPLACE(K26:O26, ""[^0-9]"", """")), 0)), rata, IFERROR(AVERAGEIF(angka_murni, "">0""), 0), IF(rata > 0, IF(rata > 500, ""SANGAT OPTIMAL"", IF(rata > 200, ""OPTIMAL"", IF(rata > 100, "&"""KURANG OPTIMAL"", ""TIDAK OPTIMAL""))), IF(COUNTIF(K26:O26, ""*TIDAK TERDETEKSI*"") > 0, ""TIDAK TERDETEKSI"", IF(COUNTIF(K26:O26, ""*TIDAK AKTIF*"") > 0, ""TIDAK AKTIF"", IF(COUNTIF(K26:O26, ""*BELUM TERPASANG*"") > 0, ""BELUM TERPASAN"&"G"", ""TIDAK AKTIF""))) ) )"),"TIDAK AKTIF") -> TIDAK AKTIF | T26: PERANGKAT DIMATIKAN KARENA KETIKA DIHIDUPKAN MENGGANGGU PERANGKAT LAIN | U26: PLN | V26: 4794 | W26: SMKN 1, SMAN 1 & SMAN 2 MUARA BADAK | X26: 604950 | Y26: https://tanjunglimau.digitaldesa.id/
